Workbook
Name IQ_CH: 110000
Name IQ_CQ: 5000
Name IQ_CY: 10000
Name IQ_DAILY: 500000
Name IQ_FH: 100000
Name IQ_FQ: 500
Name IQ_FY: 1000
Name IQ_LTM: 2000
Name IQ_MONTH: 15000
Name IQ_NTM: 6000
Name IQ_WEEK: 50000
Name IQ_YTD: 3000
Name UPDATE: #REF!
Name UPDATE: 'Data Sheet'!$E$1

Sheet one page
B2: ='Data Sheet'!B1&" - One Page Report" -> HINDUSTAN UNILEVER LTD - One Page Report
C4: ='input sheet'!I1 -> Hindustan Unilever Limited (HUL) is an Indian fast-moving consumer goods company, headquartered in Mumbai.[3] It is a subsidiary of the Anglo-Dutch company Unilever. Its products include foods, beverages, cleaning agents, personal care products and other consumer staples. However, the integration of GSK's 3,800 employees remained uncertain as HUL stated there was no clause for retention of employees in the deal.
B5: INR (Crs)
B6: Key Financial Metrics | C6: ='Data Sheet'!G16 -> 44286 | D6: ='Data Sheet'!H16 -> 44651 | E6: ='Data Sheet'!I16 -> 45016 | F6: ='Data Sheet'!J16 -> 45382 | G6: ='Data Sheet'!K16 -> 45747 | I6: Share Price - 5Y
B8: Total sales | C8: ='Data Sheet'!G17 -> 47028 | D8: ='Data Sheet'!H17 -> 52446 | E8: ='Data Sheet'!I17 -> 60580 | F8: ='Data Sheet'!J17 -> 61896 | G8: ='Data Sheet'!K17 -> 63121
B9: Sales Growth (Y-O-Y) | C9: ='Profit & Loss'!G28 -> 0.18211296 | D9: ='Profit & Loss'!H28 -> 0.11520796 | E9: ='Profit & Loss'!I28 -> 0.15509286 | F9: ='Profit & Loss'!J28 -> 0.021723341 | G9: ='Profit & Loss'!K28 -> 0.019791263
B10: Gross Prifit Margin (%) | C10: ='Profit & Loss'!G30 -> 0.49491792 | D10: ='Profit & Loss'!H30 -> 0.49347901 | E10: ='Profit & Loss'!I30 -> 0.46059756 | F10: ='Profit & Loss'!J30 -> 0.50458834 | G10: ='Profit & Loss'!K30 -> 0.49687109
B11: EBITDA Margin (%) | C11: ='Profit & Loss'!G31 -> 0.24721443 | D11: ='Profit & Loss'!H31 -> 0.24514739 | E11: ='Profit & Loss'!I31 -> 0.23352592 | F11: ='Profit & Loss'!J31 -> 0.23683275 | G11: ='Profit & Loss'!K31 -> 0.23515153
B12: EBIT Margin (%) | C12: ='Profit & Loss'!G33 -> 0.22799183 | D12: ='Profit & Loss'!H33 -> 0.22852076 | E12: ='Profit & Loss'!I33 -> 0.22215253 | F12: ='Profit & Loss'!J33 -> 0.23038645 | G12: ='Profit & Loss'!K33 -> 0.23462873
B13: Net profit Margin (%) | C13: ='Profit & Loss'!G35 -> 0.1700051 | D13: ='Profit & Loss'!H35 -> 0.16929794 | E13: ='Profit & Loss'!I35 -> 0.16705183 | F13: ='Profit & Loss'!J35 -> 0.16603658 | G13: ='Profit & Loss'!K35 -> 0.16870772
B14: Earnings Per Share (In Rs) | C14: ='Profit & Loss'!G13 -> 34.027068 | D14: ='Profit & Loss'!H13 -> 37.789411 | E14: ='Profit & Loss'!I13 -> 43.071161 | F14: ='Profit & Loss'!J13 -> 43.73936 | G14: ='Profit & Loss'!K13 -> 45.322608
B15: EPS Growth (Y-O-Y) | C15: ='Profit & Loss'!G37 -> 0.091609332 | D15: ='Profit & Loss'!H37 -> 0.11056911 | E15: ='Profit & Loss'!I37 -> 0.13976799 | F15: ='Profit & Loss'!J37 -> 0.015513834 | G15: ='Profit & Loss'!K37 -> 0.036197334
B16: Dividend Per Share (In Rs) | C16: ='Profit & Loss'!G39 -> 40.506895 | D16: ='Profit & Loss'!H39 -> 34.005788 | E16: ='Profit & Loss'!I39 -> 39.006639 | F16: ='Profit & Loss'!J39 -> 42.00715 | G16: ='Profit & Loss'!K39 -> 53.009023
B17: DPS Growth (Y-O-Y) | C17: ='Profit & Loss'!G40 -> 0.6238764 | D17: ='Profit & Loss'!H40 -> -0.16049383 | E17: ='Profit & Loss'!I40 -> 0.14705882 | F17: ='Profit & Loss'!J40 -> 0.076923077 | G17: ='Profit & Loss'!K40 -> 0.26190476
B20: Key Financial Ratios | C20: =C6 -> 44286 | D20: =D6 -> 44651 | E20: =E6 -> 45016 | F20: =F6 -> 45382 | G20: =G6 -> 45747 | I20: VOLUME- 5Y
B22: Price To Earnings | C22: ='Profit & Loss'!G14 -> 71.457816 | D22: ='Profit & Loss'!H14 -> 54.212277 | E22: ='Profit & Loss'!I14 -> 59.444648 | F22: ='Profit & Loss'!J14 -> 51.769162 | G22: ='Profit & Loss'!K14 -> 49.839365
B23: Ev / EBITDA | C23: ='Profit & Loss'!G47 -> 48.755741 | D23: ='Profit & Loss'!H47 -> 37.220798 | E23: ='Profit & Loss'!I47 -> 42.278987 | F23: ='Profit & Loss'!J47 -> 35.879438 | G23: ='Profit & Loss'!K47 -> 35.358984
B24: EV / Sales | C24: ='Profit & Loss'!G48 -> 12.053122 | D24: ='Profit & Loss'!H48 -> 9.1245816 | E24: ='Profit & Loss'!I48 -> 9.8732393 | F24: ='Profit & Loss'!J48 -> 8.4974259 | G24: ='Profit & Loss'!K48 -> 8.3147193
B25: Price To Book Value | C25: ='Profit & Loss'!G50 -> 11.983581 | D25: ='Profit & Loss'!H50 -> 9.8112718 | E25: ='Profit & Loss'!I50 -> 11.958887 | F25: ='Profit & Loss'!J50 -> 10.387592 | G25: ='Profit & Loss'!K50 -> 10.743278
B26: Return on Equity (%) | C26: ='Balance Sheet'!G23 -> 0.16770147 | D26: ='Balance Sheet'!H23 -> 0.18097878 | E26: ='Balance Sheet'!I23 -> 0.20117684 | F26: ='Balance Sheet'!J23 -> 0.20065211 | G26: ='Balance Sheet'!K23 -> 0.21555807
B27: Return On Capital Employed (%) | C27: ='Balance Sheet'!G24 -> 0.38359301 | D27: ='Balance Sheet'!H24 -> 0.24514717 | E27: ='Balance Sheet'!I24 -> 0.26485088 | F27: ='Balance Sheet'!J24 -> 0.27363876 | G27: ='Balance Sheet'!K24 -> 0.28548847
B29: Top 10 Shareholders | C29: ='itc share price'!J46 -> No Of Shares | E29: ='itc share price'!K46 -> % Holding | F29: ='itc share price'!L46 -> Market value (In Crs) | I29: Shareholder Pattern
B31: ='input sheet'!C35 -> UNILEVER PLC | C31: ='input sheet'!D35 -> 111.43701 | E31: ='input sheet'!E35 -> 0.4743 | F31: ='input sheet'!G35 -> 281813.07
B32: ='input sheet'!C36 -> LICI INDEX PLUS FLEXI SMART GROWTH FUND | C32: ='input sheet'!D36 -> 15.131235 | E32: ='input sheet'!E36 -> 0.0644 | F32: ='input sheet'!G36 -> 38265.381
B33: ='input sheet'!C37 -> UNILEVER GROUP LIMITED | C33: ='input sheet'!D37 -> 10.673946 | E33: ='input sheet'!E37 -> 0.0454 | F33: ='input sheet'!G37 -> 26993.342
B34: ='input sheet'!C38 -> UNILEVER OVERSEAS HOLDINGS AG | C34: ='input sheet'!D38 -> 6.878432 | E34: ='input sheet'!E38 -> 0.0293 | F34: ='input sheet'!G38 -> 17394.867
B35: ='input sheet'!C39 -> UNILEVER UK&CN HOLDINGS LIMITED | C35: ='input sheet'!D39 -> 6.008625 | E35: ='input sheet'!E39 -> 0.0256 | F35: ='input sheet'!G39 -> 15195.212
B36: ='input sheet'!C40 -> UNILEVER SOUTH INDIA ESTATES LIMITED | C36: ='input sheet'!D40 -> 5.27472 | E36: ='input sheet'!E40 -> 0.0224 | F36: ='input sheet'!G40 -> 13339.239
B37: ='input sheet'!C41 -> SBI NIFTY 200 QUALITY 30 ETF | C37: ='input sheet'!D41 -> 3.9300417 | E37: ='input sheet'!E41 -> 0.0167 | F37: ='input sheet'!G41 -> 9938.6825
B38: ='input sheet'!C42 -> ICICI PRUDENTIAL MUTUAL FUND | C38: ='input sheet'!D42 -> 3.4360582 | E38: ='input sheet'!E42 -> 0.0146 | F38: ='input sheet'!G42 -> 8689.4476
B39: ='input sheet'!C43 -> UNILEVER ASSAM ESTATES LIMITED | C39: ='input sheet'!D43 -> 3.282048 | E39: ='input sheet'!E43 -> 0.014 | F39: ='input sheet'!G43 -> 8299.9712
B40: ='input sheet'!C44 -> UNILEVER OVERSEAS HOLDINGS B V | C40: ='input sheet'!D44 -> 1.8865 | E40: ='input sheet'!E44 -> 0.008 | F40: ='input sheet'!G44 -> 4770.7699
B42: Managerial Remuneration | C42: Designation | D42: Remuneration | F42: X of Median Salaray | I42: Capital Structure
B44: Rohit Jawa | C44: CEO & MD | E44: 22.392321 | G44: 146 | I44: Share Price on xxx | K44: ='Data Sheet'!B8 -> 2528.9
B45: Ritesh Tiwari | C45: Executive Director & CFO | E45: 8.5560788 | G45: 59 | I45: Number Of shares o/s | K45: ='Data Sheet'!B6 -> 244.7425
B46: BP Biddappa | C46: Executive Director & SO | E46: 7.9375613 | G46: 66 | I46: Market Capitalization | K46: =K45*K44 -> 618929.3
B47: Dev Bajpai | C47: Executive Director & CS | E47: 10.379239 | G47: 83 | I47: Less: Cash & Equivalents | K47: ='Data Sheet'!K69*-1 -> -7554
I48: Add: Total Debt | K48: ='Data Sheet'!K59 -> 1648 | P48: 10000000
I49: Add: Minority Interest | K49: 367.89
I50: Enerprise Value | K50: =SUM(K46:K49) -> 613391.19
...

Sheet HistoricalFS
B3: ='Data Sheet'!B1 -> HINDUSTAN UNILEVER LTD
B4: =CONCATENATE("(",B3," |"," BSE Code :",'Data Sheet'!B4,")") -> (HINDUSTAN UNILEVER LTD | BSE Code :500696)
B5: =CONCATENATE(,"INR ",'Data Sheet'!B8) -> INR 2528.9
B6: 52 week (High - INR 3,022.9 & Low - 2,136.0)
B10: ="Historical Financial Statement - "&'Data Sheet'!B1 -> Historical Financial Statement - HINDUSTAN UNILEVER LTD
B11: Years | C11: ='[1]Data Sheet'!B16 -> 42460 | D11: ='[1]Data Sheet'!C16 -> 42825 | E11: ='[1]Data Sheet'!D16 -> 43190 | F11: ='[1]Data Sheet'!E16 -> 43555 | G11: ='[1]Data Sheet'!F16 -> 43921 | H11: ='[1]Data Sheet'!G16 -> 44286 | I11: ='[1]Data Sheet'!H16 -> 44651 | J11: ='[1]Data Sheet'!I16 -> 45016 | ... L11: ='[1]Data Sheet'!K16 -> 45747 | M11: LTM
A13: # | B13: Income Statement
B14: Sales | C14: ='Data Sheet'!B17 -> 32186 | D14: ='Data Sheet'!C17 -> 33162 | E14: ='Data Sheet'!D17 -> 35545 | F14: ='Data Sheet'!E17 -> 39310 | G14: ='Data Sheet'!F17 -> 39783 | H14: ='Data Sheet'!G17 -> 47028 | I14: ='Data Sheet'!H17 -> 52446 | J14: ='Data Sheet'!I17 -> 60580 | ... L14: ='Data Sheet'!K17 -> 63121 | M14: =IFERROR(SUM('Data Sheet'!H42:K42),0) -> 63928
B15: Sales Growth | C15: - | D15: =D14/C14-1 -> 0.030323743 | E15: =E14/D14-1 -> 0.071859357 | F15: =F14/E14-1 -> 0.10592207 | G15: =G14/F14-1 -> 0.012032562 | H15: =H14/G14-1 -> 0.18211296 | I15: =I14/H14-1 -> 0.11520796 | J15: =J14/I14-1 -> 0.15509286 | K15: =K14/J14-1 -> 0.021723341 | ... M15: =M14/L14-1 -> 0.012784969
B17: COGS | C17: =IFERROR(SUM('Data Sheet'!B18,'Data Sheet'!B20:B22)-'Data Sheet'!B19,0) -> 18222 | D17: =IFERROR(SUM('Data Sheet'!C18,'Data Sheet'!C20:C22)-'Data Sheet'!C19,0) -> 18675 | E17: =IFERROR(SUM('Data Sheet'!D18,'Data Sheet'!D20:D22)-'Data Sheet'!D19,0) -> 19314 | F17: =IFERROR(SUM('Data Sheet'!E18,'Data Sheet'!E20:E22)-'Data Sheet'!E19,0) -> 21081 | G17: =IFERROR(SUM('Data Sheet'!F18,'Data Sheet'!F20:F22)-'Data Sheet'!F19,0) -> 20614 | H17: =IFERROR(SUM('Data Sheet'!G18,'Data Sheet'!G20:G22)-'Data Sheet'!G19,0) -> 25301 | I17: =IFERROR(SUM('Data Sheet'!H18,'Data Sheet'!H20:H22)-'Data Sheet'!H19,0) -> 29066 | J17: =IFERROR(SUM('Data Sheet'!I18,'Data Sheet'!I20:I22)-'Data Sheet'!I19,0) -> 35381 | ... L17: =IFERROR(SUM('Data Sheet'!K18,'Data Sheet'!K20:K22)-'Data Sheet'!K19,0) -> 34529 | M17: =IFERROR(SUM('Data Sheet'!H43:K43),0) -> 49111
B18: COGS % Sales | C18: =C17/C14 -> 0.56614677 | D18: =D17/D14 -> 0.56314456 | E18: =E17/E14 -> 0.54336756 | F18: =F17/F14 -> 0.53627576 | G18: =G17/G14 -> 0.51816102 | H18: =H17/H14 -> 0.53799864 | I18: =I17/I14 -> 0.55420814 | J18: =J17/J14 -> 0.58403764 | ... M18: =M17/M14 -> 0.76822363
B20: Gross Profit | C20: =C14-C17 -> 13964 | D20: =D14-D17 -> 14487 | E20: =E14-E17 -> 16231 | F20: =F14-F17 -> 18229 | G20: =G14-G17 -> 19169 | H20: =H14-H17 -> 21727 | I20: =I14-I17 -> 23380 | J20: =J14-J17 -> 25199 | ... M20: =M14-M17 -> 14817
B21: Gross Margins | C21: =C20/C14 -> 0.43385323 | D21: =D20/D14 -> 0.43685544 | E21: =E20/E14 -> 0.45663244 | F21: =F20/F14 -> 0.46372424 | G21: =G20/G14 -> 0.48183898 | H21: =H20/H14 -> 0.46200136 | I21: =I20/I14 -> 0.44579186 | J21: =J20/J14 -> 0.41596236 | ... M21: =M20/M14 -> 0.23177637
B23: Selling & General Expenses | C23: =IFERROR(SUM('Data Sheet'!B23:B24),0) -> 8054 | D23: =IFERROR(SUM('Data Sheet'!C23:C24),0) -> 8159 | E23: =IFERROR(SUM('Data Sheet'!D23:D24),0) -> 8732 | F23: =IFERROR(SUM('Data Sheet'!E23:E24),0) -> 9349 | G23: =IFERROR(SUM('Data Sheet'!F23:F24),0) -> 9308 | H23: =IFERROR(SUM('Data Sheet'!G23:G24),0) -> 10101 | I23: =IFERROR(SUM('Data Sheet'!H23:H24),0) -> 10523 | J23: =IFERROR(SUM('Data Sheet'!I23:I24),0) -> 11052 | ... L23: =IFERROR(SUM('Data Sheet'!K23:K24),0) -> 13749
B24: S&G Exp % Sales | C24: =C23/C14 -> 0.25023302 | D24: =D23/D14 -> 0.24603462 | E24: =E23/E14 -> 0.24566043 | F24: =F23/F14 -> 0.23782752 | G24: =G23/G14 -> 0.23396928 | H24: =H23/H14 -> 0.21478694 | I24: =I23/I14 -> 0.20064447 | J24: =J23/J14 -> 0.18243645 | ... M24: =M23/M14 -> 0
B26: EBITDA | C26: =C20-C23 -> 5910 | D26: =D20-D23 -> 6328 | E26: =E20-E23 -> 7499 | F26: =F20-F23 -> 8880 | G26: =G20-G23 -> 9861 | H26: =H20-H23 -> 11626 | I26: =I20-I23 -> 12857 | J26: =J20-J23 -> 14147 | ... L26: =L20-L23 -> 14843 | M26: =IFERROR(SUM('Data Sheet'!H52:K52),0) -> 15973
B27: EBITDA Margins | C27: =C26/C14 -> 0.18362021 | D27: =D26/D14 -> 0.19082082 | E27: =E26/E14 -> 0.21097201 | F27: =F26/F14 -> 0.22589672 | G27: =G26/G14 -> 0.24786969 | H27: =H26/H14 -> 0.24721443 | I27: =I26/I14 -> 0.24514739 | J27: =J26/J14 -> 0.23352592 | ... M27: =M26/M14 -> 0.24985922
B29: Interest | C29: ='Data Sheet'!B27 -> 17 | D29: ='Data Sheet'!C27 -> 35 | E29: ='Data Sheet'!D27 -> 26 | F29: ='Data Sheet'!E27 -> 33 | G29: ='Data Sheet'!F27 -> 118 | H29: ='Data Sheet'!G27 -> 117 | I29: ='Data Sheet'!H27 -> 106 | J29: ='Data Sheet'!I27 -> 114 | ... L29: ='Data Sheet'!K27 -> 395 | M29: =IFERROR(SUM('Data Sheet'!H46:K46),0) -> 429
B30: Interest % Sales | C30: =C29/C14 -> 0.00052817995 | D30: =D29/D14 -> 0.0010554249 | E30: =E29/E14 -> 0.00073146715 | F30: =F29/F14 -> 0.00083948105 | G30: =G29/G14 -> 0.002966091 | H30: =H29/H14 -> 0.0024878796 | I30: =I29/I14 -> 0.0020211265 | J30: =J29/J14 -> 0.0018818092 | ... M30: =M29/M14 -> 0.0067106745
B32: Depreciation | C32: ='Data Sheet'!B26 -> 353 | D32: ='Data Sheet'!C26 -> 432 | E32: ='Data Sheet'!D26 -> 520 | F32: ='Data Sheet'!E26 -> 565 | G32: ='Data Sheet'!F26 -> 1002 | H32: ='Data Sheet'!G26 -> 1074 | I32: ='Data Sheet'!H26 -> 1091 | J32: ='Data Sheet'!I26 -> 1137 | ... L32: ='Data Sheet'!K26 -> 1355 | M32: =IFERROR(SUM('Data Sheet'!H45:K45),0) -> 1387
B33: Depreciation%Sales | C33: =C32/C14 -> 0.010967501 | D33: =D32/D14 -> 0.013026959 | E33: =E32/E14 -> 0.014629343 | F33: =F32/F14 -> 0.014372933 | G33: =G32/G14 -> 0.025186638 | H33: =H32/H14 -> 0.022837459 | I33: =I32/I14 -> 0.020802349 | J33: =J32/J14 -> 0.01876857 | ... M33: =M32/M14 -> 0.021696283
B35: EBIT | C35: =C26-C32 -> 5557 | D35: =D26-D32 -> 5896 | E35: =E26-E32 -> 6979 | F35: =F26-F32 -> 8315 | G35: =G26-G32 -> 8859 | H35: =H26-H32 -> 10552 | I35: =I26-I32 -> 11766 | J35: =J26-J32 -> 13010 | ... M35: =M26-M32 -> 14586
B36: EBIT % Sales | C36: =C35/C14 -> 0.17265271 | D36: =D35/D14 -> 0.17779386 | E36: =E35/E14 -> 0.19634266 | F36: =F35/F14 -> 0.21152379 | G36: =G35/G14 -> 0.22268306 | H36: =H35/H14 -> 0.22437697 | I36: =I35/I14 -> 0.22434504 | J36: =J35/J14 -> 0.21475735 | ... M36: =M35/M14 -> 0.22816293
B38: Earnings Before Tax | C38: =IFERROR(C26-SUM(C32,C29),0) -> 5540 | D38: =IFERROR(D26-SUM(D32,D29),0) -> 5861 | E38: =IFERROR(E26-SUM(E32,E29),0) -> 6953 | F38: =IFERROR(F26-SUM(F32,F29),0) -> 8282 | G38: =IFERROR(G26-SUM(G32,G29),0) -> 8741 | H38: =IFERROR(H26-SUM(H32,H29),0) -> 10435 | I38: =IFERROR(I26-SUM(I32,I29),0) -> 11660 | J38: =IFERROR(J26-SUM(J32,J29),0) -> 12896 | ... M38: =IFERROR(M26-SUM(M32,M29),0) -> 14157
B39: EBT % Sales | C39: =C38/C14 -> 0.17212453 | D39: =D38/D14 -> 0.17673844 | E39: =E38/E14 -> 0.1956112 | F39: =F38/F14 -> 0.2106843 | G39: =G38/G14 -> 0.21971696 | H39: =H38/H14 -> 0.22188909 | I39: =I38/I14 -> 0.22232391 | J39: =J38/J14 -> 0.21287554 | ... M39: =M38/M14 -> 0.22145226
B41: Tax | C41: =IFERROR('Data Sheet'!B29,0) -> 1875 | D41: =IFERROR('Data Sheet'!C29,0) -> 1977 | E41: =IFERROR('Data Sheet'!D29,0) -> 2079 | F41: =IFERROR('Data Sheet'!E29,0) -> 2544 | G41: =IFERROR('Data Sheet'!F29,0) -> 2409 | H41: =IFERROR('Data Sheet'!G29,0) -> 2606 | I41: =IFERROR('Data Sheet'!H29,0) -> 2987 | J41: =IFERROR('Data Sheet'!I29,0) -> 3201 | ... L41: =IFERROR('Data Sheet'!K29,0) -> 3744 | M41: =IFERROR(SUM('Data Sheet'!H48:K48),0) -> 3362
B42: Effective Tax Rate | C42: =C41/C38 -> 0.33844765 | D42: =D41/D38 -> 0.33731445 | E42: =E41/E38 -> 0.29900762 | F42: =F41/F38 -> 0.30717218 | G42: =G41/G38 -> 0.27559776 | H42: =H41/H38 -> 0.24973646 | I42: =I41/I38 -> 0.25617496 | J42: =J41/J38 -> 0.2482165 | ... M42: =M41/M38 -> 0.23747969
B44: Net Profit | C44: =IFERROR(C38-C41,0) -> 3665 | D44: =IFERROR(D38-D41,0) -> 3884 | E44: =IFERROR(E38-E41,0) -> 4874 | F44: =IFERROR(F38-F41,0) -> 5738 | G44: =IFERROR(G38-G41,0) -> 6332 | H44: =IFERROR(H38-H41,0) -> 7829 | I44: =IFERROR(I38-I41,0) -> 8673 | J44: =IFERROR(J38-J41,0) -> 9695 | ... M44: =IFERROR(M38-M41,0) -> 10795
B45: Net Margins | C45: =C44/C14 -> 0.11386938 | D45: =D44/D14 -> 0.11712201 | E45: =E44/E14 -> 0.13712196 | F45: =F44/F14 -> 0.14596795 | G45: =G44/G14 -> 0.15916346 | H45: =H44/H14 -> 0.16647529 | I45: =I44/I14 -> 0.16537009 | J45: =J44/J14 -> 0.16003632 | ... M45: =M44/M14 -> 0.16886184
B47: No of Equity Shares | C47: =IFERROR('Data Sheet'!B93,0) -> 216.39 | D47: =IFERROR('Data Sheet'!C93,0) -> 216.43 | E47: =IFERROR('Data Sheet'!D93,0) -> 216.45 | F47: =IFERROR('Data Sheet'!E93,0) -> 216.47 | G47: =IFERROR('Data Sheet'!F93,0) -> 216.48 | H47: =IFERROR('Data Sheet'!G93,0) -> 234.96 | I47: =IFERROR('Data Sheet'!H93,0) -> 234.96 | J47: =IFERROR('Data Sheet'!I93,0) -> 234.96 | ... L47: =IFERROR('Data Sheet'!K93,0) -> 234.96 | M47: =L47 -> 234.96
B49: Earnings per Share | C49: =IFERROR(C44/C47,0) -> 16.937012 | D49: =IFERROR(D44/D47,0) -> 17.945756 | E49: =IFERROR(E44/E47,0) -> 22.517903 | F49: =IFERROR(F44/F47,0) -> 26.507137 | G49: =IFERROR(G44/G47,0) -> 29.249815 | H49: =IFERROR(H44/H47,0) -> 33.320565 | I49: =IFERROR(I44/I47,0) -> 36.912666 | J49: =IFERROR(J44/J47,0) -> 41.262343 | ... M49: =IFERROR(M44/M47,0) -> 45.94399
B50: EPS Growth % | D50: =IFERROR(D49/C49-1,0) -> 0.059558573 | E50: =IFERROR(E49/D49-1,0) -> 0.25477591 | F50: =IFERROR(F49/E49-1,0) -> 0.17715836 | G50: =IFERROR(G49/F49-1,0) -> 0.10346941 | H50: =IFERROR(H49/G49-1,0) -> 0.13917182 | I50: =IFERROR(I49/H49-1,0) -> 0.10780432 | J50: =IFERROR(J49/I49-1,0) -> 0.11783697 | K50: =IFERROR(K49/J49-1,0) -> -0.023723569 | ... M50: =IFERROR(M49/L49-1,0) -> 0.15466895
B52: Dividend per Share | C52: =IFERROR('Data Sheet'!B31/HistoricalFS!C47,0) -> 15.971163 | D52: =IFERROR('Data Sheet'!C31/HistoricalFS!D47,0) -> 16.966225 | E52: =IFERROR('Data Sheet'!D31/HistoricalFS!E47,0) -> 19.95842 | F52: =IFERROR('Data Sheet'!E31/HistoricalFS!F47,0) -> 21.952234 | G52: =IFERROR('Data Sheet'!F31/HistoricalFS!G47,0) -> 24.944568 | H52: =IFERROR('Data Sheet'!G31/HistoricalFS!H47,0) -> 40.506895 | I52: =IFERROR('Data Sheet'!H31/HistoricalFS!I47,0) -> 34.005788 | J52: =IFERROR('Data Sheet'!I31/HistoricalFS!J47,0) -> 39.006639 | ... M52: =IFERROR('Data Sheet'!L31/HistoricalFS!M47,0) -> 0
B53: Dividend payout ratio | C53: =IFERROR(C52/C49,0) -> 0.94297408 | D53: =IFERROR(D52/D49,0) -> 0.9454171 | E53: =IFERROR(E52/E49,0) -> 0.88633566 | F53: =IFERROR(F52/F49,0) -> 0.82816312 | G53: =IFERROR(G52/G49,0) -> 0.85281112 | H53: =IFERROR(H52/H49,0) -> 1.2156725 | I53: =IFERROR(I52/I49,0) -> 0.92124986 | J53: =IFERROR(J52/J49,0) -> 0.94533265 | ... M53: =IFERROR(M52/M49,0) -> 0
B55: Retained Earnings | C55: =IFERROR(IF(C49>C52,1-C53,0),0) -> 0.057025921 | D55: =IFERROR(IF(D49>D52,1-D53,0),0) -> 0.054582904 | E55: =IFERROR(IF(E49>E52,1-E53,0),0) -> 0.11366434 | F55: =IFERROR(IF(F49>F52,1-F53,0),0) -> 0.17183688 | G55: =IFERROR(IF(G49>G52,1-G53,0),0) -> 0.14718888 | H55: =IFERROR(IF(H49>H52,1-H53,0),0) -> 0 | I55: =IFERROR(IF(I49>I52,1-I53,0),0) -> 0.078750144 | J55: =IFERROR(IF(J49>J52,1-J53,0),0) -> 0.054667354 | ... M55: =IFERROR(IF(M49>M52,1-M53,0),0) -> 1
B62: ='Data Sheet'!B1 -> HINDUSTAN UNILEVER LTD
B63: =CONCATENATE("(",B62," |"," BSE Code :","500696",")") -> (HINDUSTAN UNILEVER LTD | BSE Code :500696)
B64: =CONCATENATE(,"INR ",'Data Sheet'!B8) -> INR 2528.9
B65: 52 week (High - INR 3,022.9 & Low - 2,136.0)
A70: # | B70: Balance Sheet
...

Sheet common size
B3: ='Data Sheet'!B1 -> HINDUSTAN UNILEVER LTD
B4: =CONCATENATE("(",B3," |"," BSE Code :",'Data Sheet'!B4,")") -> (HINDUSTAN UNILEVER LTD | BSE Code :500696)
B5: =CONCATENATE(,"INR ",'Data Sheet'!B8) -> INR 2528.9
B6: 52 week (High - INR 3,022.9 & Low - 2,136.0)
A8: # | B8: ="Common Size Statemment"&" "&" - "&'Data Sheet'!B1 -> Common Size Statemment - HINDUSTAN UNILEVER LTD
B10: Particular | C10: ='Data Sheet'!B16 -> 42460 | D10: ='Data Sheet'!C16 -> 42825 | E10: ='Data Sheet'!D16 -> 43190 | F10: ='Data Sheet'!E16 -> 43555 | G10: ='Data Sheet'!F16 -> 43921 | H10: ='Data Sheet'!G16 -> 44286 | I10: ='Data Sheet'!H16 -> 44651 | J10: ='Data Sheet'!I16 -> 45016 | ... L10: ='Data Sheet'!K16 -> 45747
B12: ='[2]Data Sheet'!A17 -> Sales | C12: ='Data Sheet'!B17/'Data Sheet'!B$17 -> 1 | D12: ='Data Sheet'!C17/'Data Sheet'!C$17 -> 1 | E12: ='Data Sheet'!D17/'Data Sheet'!D$17 -> 1 | F12: ='Data Sheet'!E17/'Data Sheet'!E$17 -> 1 | G12: ='Data Sheet'!F17/'Data Sheet'!F$17 -> 1 | H12: ='Data Sheet'!G17/'Data Sheet'!G$17 -> 1 | I12: ='Data Sheet'!H17/'Data Sheet'!H$17 -> 1 | J12: ='Data Sheet'!I17/'Data Sheet'!I$17 -> 1 | ... L12: ='Data Sheet'!K17/'Data Sheet'!K$17 -> 1
B13: ='[2]Data Sheet'!A18 -> Raw Material Cost | C13: ='Data Sheet'!B18/'Data Sheet'!B$17 -> 0.40961909 | D13: ='Data Sheet'!C18/'Data Sheet'!C$17 -> 0.41028888 | E13: ='Data Sheet'!D18/'Data Sheet'!D$17 -> 0.400422 | F13: ='Data Sheet'!E18/'Data Sheet'!E$17 -> 0.4030781 | G13: ='Data Sheet'!F18/'Data Sheet'!F$17 -> 0.39456552 | H13: ='Data Sheet'!G18/'Data Sheet'!G$17 -> 0.42827677 | I13: ='Data Sheet'!H18/'Data Sheet'!H$17 -> 0.43608664 | J13: ='Data Sheet'!I18/'Data Sheet'!I$17 -> 0.46924728 | ... L13: ='Data Sheet'!K18/'Data Sheet'!K$17 -> 0.43319973
B14: ='[2]Data Sheet'!A19 -> Change in Inventory | C14: ='Data Sheet'!B19/'Data Sheet'!B$17 -> -0.002578761 | D14: ='Data Sheet'!C19/'Data Sheet'!C$17 -> -0.0043423195 | E14: ='Data Sheet'!D19/'Data Sheet'!D$17 -> 0.0020256014 | F14: ='Data Sheet'!E19/'Data Sheet'!E$17 -> -0.00030526584 | G14: ='Data Sheet'!F19/'Data Sheet'!F$17 -> 0.0027147274 | H14: ='Data Sheet'!G19/'Data Sheet'!G$17 -> 0.0086118908 | I14: ='Data Sheet'!H19/'Data Sheet'!H$17 -> 0.00041947908 | J14: ='Data Sheet'!I19/'Data Sheet'!I$17 -> 0.0012380324 | ... L14: ='Data Sheet'!K19/'Data Sheet'!K$17 -> 0.002423916
B15: ='[2]Data Sheet'!A20 -> Power and Fuel | C15: ='Data Sheet'!B20/'Data Sheet'!B$17 -> 0.0096004474 | D15: ='Data Sheet'!C20/'Data Sheet'!C$17 -> 0.008895724 | E15: ='Data Sheet'!D20/'Data Sheet'!D$17 -> 0.0082993389 | F15: ='Data Sheet'!E20/'Data Sheet'!E$17 -> 0.0078351564 | G15: ='Data Sheet'!F20/'Data Sheet'!F$17 -> 0.0075157731 | H15: ='Data Sheet'!G20/'Data Sheet'!G$17 -> 0.0072084715 | I15: ='Data Sheet'!H20/'Data Sheet'!H$17 -> 0.0060633795 | J15: ='Data Sheet'!I20/'Data Sheet'!I$17 -> 0.0063387257 | ... L15: ='Data Sheet'!K20/'Data Sheet'!K$17 -> 0.0067647851
B16: ='[2]Data Sheet'!A21 -> Other Mfr. Exp | C16: ='Data Sheet'!B21/'Data Sheet'!B$17 -> 0.092151867 | D16: ='Data Sheet'!C21/'Data Sheet'!C$17 -> 0.087057475 | E16: ='Data Sheet'!D21/'Data Sheet'!D$17 -> 0.08434379 | F16: ='Data Sheet'!E21/'Data Sheet'!E$17 -> 0.077359451 | G16: ='Data Sheet'!F21/'Data Sheet'!F$17 -> 0.073046276 | H16: ='Data Sheet'!G21/'Data Sheet'!G$17 -> 0.060984945 | I16: ='Data Sheet'!H21/'Data Sheet'!H$17 -> 0.063951493 | J16: ='Data Sheet'!I21/'Data Sheet'!I$17 -> 0.062578409 | ... L16: ='Data Sheet'!K21/'Data Sheet'!K$17 -> 0.060740483
B17: ='[2]Data Sheet'!A22 -> Employee Cost | C17: ='Data Sheet'!B22/'Data Sheet'!B$17 -> 0.052196607 | D17: ='Data Sheet'!C22/'Data Sheet'!C$17 -> 0.052560159 | E17: ='Data Sheet'!D22/'Data Sheet'!D$17 -> 0.052328035 | F17: ='Data Sheet'!E22/'Data Sheet'!E$17 -> 0.047697787 | G17: ='Data Sheet'!F22/'Data Sheet'!F$17 -> 0.045748184 | H17: ='Data Sheet'!G22/'Data Sheet'!G$17 -> 0.050140342 | I17: ='Data Sheet'!H22/'Data Sheet'!H$17 -> 0.048526103 | J17: ='Data Sheet'!I22/'Data Sheet'!I$17 -> 0.047111258 | ... L17: ='Data Sheet'!K22/'Data Sheet'!K$17 -> 0.048747643
B18: ='[2]Data Sheet'!A23 -> Selling and admin | C18: ='Data Sheet'!B23/'Data Sheet'!B$17 -> 0.20943889 | D18: ='Data Sheet'!C23/'Data Sheet'!C$17 -> 0.20170677 | E18: ='Data Sheet'!D23/'Data Sheet'!D$17 -> 0.20402307 | F18: ='Data Sheet'!E23/'Data Sheet'!E$17 -> 0.19832104 | G18: ='Data Sheet'!F23/'Data Sheet'!F$17 -> 0.1915391 | H18: ='Data Sheet'!G23/'Data Sheet'!G$17 -> 0.16811261 | I18: ='Data Sheet'!H23/'Data Sheet'!H$17 -> 0.15566487 | J18: ='Data Sheet'!I23/'Data Sheet'!I$17 -> 0.14501486 | ... L18: ='Data Sheet'!K23/'Data Sheet'!K$17 -> 0.16940479
B19: ='[2]Data Sheet'!A24 -> Other Expenses | C19: ='Data Sheet'!B24/'Data Sheet'!B$17 -> 0.040794134 | D19: ='Data Sheet'!C24/'Data Sheet'!C$17 -> 0.044327845 | E19: ='Data Sheet'!D24/'Data Sheet'!D$17 -> 0.041637361 | F19: ='Data Sheet'!E24/'Data Sheet'!E$17 -> 0.039506487 | G19: ='Data Sheet'!F24/'Data Sheet'!F$17 -> 0.042430184 | H19: ='Data Sheet'!G24/'Data Sheet'!G$17 -> 0.046674322 | I19: ='Data Sheet'!H24/'Data Sheet'!H$17 -> 0.044979598 | J19: ='Data Sheet'!I24/'Data Sheet'!I$17 -> 0.037421591 | ... L19: ='Data Sheet'!K24/'Data Sheet'!K$17 -> 0.048414949
B20: ='[2]Data Sheet'!A25 -> Other Income | C20: ='Data Sheet'!B25/'Data Sheet'!B$17 -> 0.015099733 | D20: ='Data Sheet'!C25/'Data Sheet'!C$17 -> 0.018273928 | E20: ='Data Sheet'!D25/'Data Sheet'!D$17 -> 0.0099310733 | F20: ='Data Sheet'!E25/'Data Sheet'!E$17 -> 0.0081912999 | G20: ='Data Sheet'!F25/'Data Sheet'!F$17 -> 0.010657819 | H20: ='Data Sheet'!G25/'Data Sheet'!G$17 -> 0.0036148677 | I20: ='Data Sheet'!H25/'Data Sheet'!H$17 -> 0.0041757236 | J20: ='Data Sheet'!I25/'Data Sheet'!I$17 -> 0.0073951799 | ... L20: ='Data Sheet'!K25/'Data Sheet'!K$17 -> 0.020943901
B21: ='[2]Data Sheet'!A26 -> Depreciation | C21: ='Data Sheet'!B26/'Data Sheet'!B$17 -> 0.010967501 | D21: ='Data Sheet'!C26/'Data Sheet'!C$17 -> 0.013026959 | E21: ='Data Sheet'!D26/'Data Sheet'!D$17 -> 0.014629343 | F21: ='Data Sheet'!E26/'Data Sheet'!E$17 -> 0.014372933 | G21: ='Data Sheet'!F26/'Data Sheet'!F$17 -> 0.025186638 | H21: ='Data Sheet'!G26/'Data Sheet'!G$17 -> 0.022837459 | I21: ='Data Sheet'!H26/'Data Sheet'!H$17 -> 0.020802349 | J21: ='Data Sheet'!I26/'Data Sheet'!I$17 -> 0.01876857 | ... L21: ='Data Sheet'!K26/'Data Sheet'!K$17 -> 0.021466707
B22: ='[2]Data Sheet'!A27 -> Interest | C22: ='Data Sheet'!B27/'Data Sheet'!B$17 -> 0.00052817995 | D22: ='Data Sheet'!C27/'Data Sheet'!C$17 -> 0.0010554249 | E22: ='Data Sheet'!D27/'Data Sheet'!D$17 -> 0.00073146715 | F22: ='Data Sheet'!E27/'Data Sheet'!E$17 -> 0.00083948105 | G22: ='Data Sheet'!F27/'Data Sheet'!F$17 -> 0.002966091 | H22: ='Data Sheet'!G27/'Data Sheet'!G$17 -> 0.0024878796 | I22: ='Data Sheet'!H27/'Data Sheet'!H$17 -> 0.0020211265 | J22: ='Data Sheet'!I27/'Data Sheet'!I$17 -> 0.0018818092 | ... L22: ='Data Sheet'!K27/'Data Sheet'!K$17 -> 0.0062578223
B23: ='[2]Data Sheet'!A28 -> Profit before tax | C23: ='Data Sheet'!B28/'Data Sheet'!B$17 -> 0.18722426 | D23: ='Data Sheet'!C28/'Data Sheet'!C$17 -> 0.19501236 | E23: ='Data Sheet'!D28/'Data Sheet'!D$17 -> 0.20554227 | F23: ='Data Sheet'!E28/'Data Sheet'!E$17 -> 0.2188756 | G23: ='Data Sheet'!F28/'Data Sheet'!F$17 -> 0.23037478 | H23: ='Data Sheet'!G28/'Data Sheet'!G$17 -> 0.22550396 | I23: ='Data Sheet'!H28/'Data Sheet'!H$17 -> 0.22649964 | J23: ='Data Sheet'!I28/'Data Sheet'!I$17 -> 0.22027072 | ... L23: ='Data Sheet'!K28/'Data Sheet'!K$17 -> 0.22837091
... B26: ='[2]Data Sheet'!A31 -> Dividend Amount | C26: ='Data Sheet'!B31/'Data Sheet'!B$17 -> 0.10737588 | D26: ='Data Sheet'!C31/'Data Sheet'!C$17 -> 0.11072915 | E26: ='Data Sheet'!D31/'Data Sheet'!D$17 -> 0.12153608 | F26: ='Data Sheet'!E31/'Data Sheet'!E$17 -> 0.12088527 | G26: ='Data Sheet'!F31/'Data Sheet'!F$17 -> 0.13573637 | H26: ='Data Sheet'!G31/'Data Sheet'!G$17 -> 0.20237943 | I26: ='Data Sheet'!H31/'Data Sheet'!H$17 -> 0.15234718 | J26: ='Data Sheet'!I31/'Data Sheet'!I$17 -> 0.15128755 | ... L26: ='Data Sheet'!K31/'Data Sheet'!K$17 -> 0.19731943
B27: ='[2]Data Sheet'!A34 -> EBITDA | C27: ='Data Sheet'!B33/'Data Sheet'!B$17 -> 0.19871994 | D27: ='Data Sheet'!C33/'Data Sheet'!C$17 -> 0.20867258 | E27: ='Data Sheet'!D33/'Data Sheet'!D$17 -> 0.22053735 | F27: ='Data Sheet'!E33/'Data Sheet'!E$17 -> 0.23393539 | G27: ='Data Sheet'!F33/'Data Sheet'!F$17 -> 0.25832642 | H27: ='Data Sheet'!G33/'Data Sheet'!G$17 -> 0.25074424 | I27: ='Data Sheet'!H33/'Data Sheet'!H$17 -> 0.24907524 | J27: ='Data Sheet'!I33/'Data Sheet'!I$17 -> 0.24054143 | ... L27: ='Data Sheet'!K33/'Data Sheet'!K$17 -> 0.2557469
A30: # | B30: ="Common Size Balance Sheet"&" "&" - "&'Data Sheet'!B1 -> Common Size Balance Sheet - HINDUSTAN UNILEVER LTD
B32: Particular | C32: ='Data Sheet'!B81 -> 42460 | D32: ='Data Sheet'!C81 -> 42825 | E32: ='Data Sheet'!D81 -> 43190 | F32: ='Data Sheet'!E81 -> 43555 | G32: ='Data Sheet'!F81 -> 43921 | H32: ='Data Sheet'!G81 -> 44286 | I32: ='Data Sheet'!H81 -> 44651 | J32: ='Data Sheet'!I81 -> 45016 | ... L32: ='Data Sheet'!K81 -> 45747
B34: Total Liability | C34: ='Data Sheet'!B61/'Data Sheet'!B$61 -> 1 | D34: ='Data Sheet'!C61/'Data Sheet'!C$61 -> 1 | E34: ='Data Sheet'!D61/'Data Sheet'!D$61 -> 1 | F34: ='Data Sheet'!E61/'Data Sheet'!E$61 -> 1 | G34: ='Data Sheet'!F61/'Data Sheet'!F$61 -> 1 | H34: ='Data Sheet'!G61/'Data Sheet'!G$61 -> 1 | I34: ='Data Sheet'!H61/'Data Sheet'!H$61 -> 1 | J34: ='Data Sheet'!I61/'Data Sheet'!I$61 -> 1 | ... L34: ='Data Sheet'!K61/'Data Sheet'!K$61 -> 1
B35: ='[2]Data Sheet'!A57 -> Equity Share Capital | C35: ='Data Sheet'!B57/'Data Sheet'!B$61 -> 0.014601501 | D35: ='Data Sheet'!C57/'Data Sheet'!C$61 -> 0.013752706 | E35: ='Data Sheet'!D57/'Data Sheet'!D$61 -> 0.012092711 | F35: ='Data Sheet'!E57/'Data Sheet'!E$61 -> 0.011594825 | G35: ='Data Sheet'!F57/'Data Sheet'!F$61 -> 0.010718007 | H35: ='Data Sheet'!G57/'Data Sheet'!G$61 -> 0.0034186791 | I35: ='Data Sheet'!H57/'Data Sheet'!H$61 -> 0.0033330497 | J35: ='Data Sheet'!I57/'Data Sheet'!I$61 -> 0.0032157861 | ... L35: ='Data Sheet'!K57/'Data Sheet'!K$61 -> 0.0029425391
B36: ='[2]Data Sheet'!A58 -> Reserves | C36: ='Data Sheet'!B58/'Data Sheet'!B$61 -> 0.42973028 | D36: ='Data Sheet'!C58/'Data Sheet'!C$61 -> 0.41563734 | E36: ='Data Sheet'!D58/'Data Sheet'!D$61 -> 0.39553242 | F36: ='Data Sheet'!E58/'Data Sheet'!E$61 -> 0.41070374 | G36: ='Data Sheet'!F58/'Data Sheet'!F$61 -> 0.3976083 | H36: ='Data Sheet'!G58/'Data Sheet'!G$61 -> 0.6901222 | I36: ='Data Sheet'!H58/'Data Sheet'!H$61 -> 0.69250844 | J36: ='Data Sheet'!I58/'Data Sheet'!I$61 -> 0.68515402 | ... L36: ='Data Sheet'!K58/'Data Sheet'!K$61 -> 0.61564179
B37: ='[2]Data Sheet'!A59 -> Borrowings | C37: ='Data Sheet'!B59/'Data Sheet'!B$61 -> 0.011965119 | D37: ='Data Sheet'!C59/'Data Sheet'!C$61 -> 0.017636572 | E37: ='Data Sheet'!D59/'Data Sheet'!D$61 -> 0 | F37: ='Data Sheet'!E59/'Data Sheet'!E$61 -> 0.0053142949 | G37: ='Data Sheet'!F59/'Data Sheet'!F$61 -> 0 | H37: ='Data Sheet'!G59/'Data Sheet'!G$61 -> 0 | I37: ='Data Sheet'!H59/'Data Sheet'!H$61 -> 0.014793067 | J37: ='Data Sheet'!I59/'Data Sheet'!I$61 -> 0.016681035 | ... L37: ='Data Sheet'!K59/'Data Sheet'!K$61 -> 0.020635338
B38: ='[2]Data Sheet'!A60 -> Other Liabilities | C38: ='Data Sheet'!B60/'Data Sheet'!B$61 -> 0.5437031 | D38: ='Data Sheet'!C60/'Data Sheet'!C$61 -> 0.55297339 | E38: ='Data Sheet'!D60/'Data Sheet'!D$61 -> 0.59237487 | F38: ='Data Sheet'!E60/'Data Sheet'!E$61 -> 0.57238714 | G38: ='Data Sheet'!F60/'Data Sheet'!F$61 -> 0.5916737 | H38: ='Data Sheet'!G60/'Data Sheet'!G$61 -> 0.30645912 | I38: ='Data Sheet'!H60/'Data Sheet'!H$61 -> 0.28936544 | J38: ='Data Sheet'!I60/'Data Sheet'!I$61 -> 0.29494916 | ... L38: ='Data Sheet'!K60/'Data Sheet'!K$61 -> 0.36078034
B40: Total Assets | C40: ='Data Sheet'!B66/'Data Sheet'!B$66 -> 1 | D40: ='Data Sheet'!C66/'Data Sheet'!C$66 -> 1 | E40: ='Data Sheet'!D66/'Data Sheet'!D$66 -> 1 | F40: ='Data Sheet'!E66/'Data Sheet'!E$66 -> 1 | G40: ='Data Sheet'!F66/'Data Sheet'!F$66 -> 1 | H40: ='Data Sheet'!G66/'Data Sheet'!G$66 -> 1 | I40: ='Data Sheet'!H66/'Data Sheet'!H$66 -> 1 | J40: ='Data Sheet'!I66/'Data Sheet'!I$66 -> 1 | ... L40: ='Data Sheet'!K66/'Data Sheet'!K$66 -> 1
B41: ='[2]Data Sheet'!A62 -> Net Block | C41: ='Data Sheet'!B62/'Data Sheet'!B$66 -> 0.2202393 | D41: ='Data Sheet'!C62/'Data Sheet'!C$66 -> 0.28135744 | E41: ='Data Sheet'!D62/'Data Sheet'!D$66 -> 0.25349905 | F41: ='Data Sheet'!E62/'Data Sheet'!E$66 -> 0.25310001 | G41: ='Data Sheet'!F62/'Data Sheet'!F$66 -> 0.27187019 | H41: ='Data Sheet'!G62/'Data Sheet'!G$66 -> 0.74837067 | I41: ='Data Sheet'!H62/'Data Sheet'!H$66 -> 0.73005134 | J41: ='Data Sheet'!I62/'Data Sheet'!I$66 -> 0.72085608 | ... L41: ='Data Sheet'!K62/'Data Sheet'!K$66 -> 0.6803526
B42: ='[2]Data Sheet'!A63 -> Capital Work in Progress | C42: ='Data Sheet'!B63/'Data Sheet'!B$66 -> 0.027580612 | D42: ='Data Sheet'!C63/'Data Sheet'!C$66 -> 0.014580415 | E42: ='Data Sheet'!D63/'Data Sheet'!D$66 -> 0.02580898 | F42: ='Data Sheet'!E63/'Data Sheet'!E$66 -> 0.021793977 | G42: ='Data Sheet'!F63/'Data Sheet'!F$66 -> 0.029623381 | H42: ='Data Sheet'!G63/'Data Sheet'!G$66 -> 0.01083794 | I42: ='Data Sheet'!H63/'Data Sheet'!H$66 -> 0.018622529 | J42: ='Data Sheet'!I63/'Data Sheet'!I$66 -> 0.01549051 | ... L42: ='Data Sheet'!K63/'Data Sheet'!K$66 -> 0.012634136
B43: ='[2]Data Sheet'!A64 -> Investments | C43: ='Data Sheet'!B64/'Data Sheet'!B$66 -> 0.17521801 | D43: ='Data Sheet'!C64/'Data Sheet'!C$66 -> 0.24156373 | E43: ='Data Sheet'!D64/'Data Sheet'!D$66 -> 0.16084425 | F43: ='Data Sheet'!E64/'Data Sheet'!E$66 -> 0.14579419 | G43: ='Data Sheet'!F64/'Data Sheet'!F$66 -> 0.062273607 | H43: ='Data Sheet'!G64/'Data Sheet'!G$66 -> 0.039409369 | I43: ='Data Sheet'!H64/'Data Sheet'!H$66 -> 0.049939012 | J43: ='Data Sheet'!I64/'Data Sheet'!I$66 -> 0.039437853 | ... L43: ='Data Sheet'!K64/'Data Sheet'!K$66 -> 0.047706698
B44: ='[2]Data Sheet'!A65 -> Other Assets | C44: ='Data Sheet'!B75/'Data Sheet'!B$66 -> 0.10383289 | D44: ='Data Sheet'!C75/'Data Sheet'!C$66 -> 0.11524258 | E44: ='Data Sheet'!D75/'Data Sheet'!D$66 -> 0.15071101 | F44: ='Data Sheet'!E75/'Data Sheet'!E$66 -> 0.14198293 | G44: ='Data Sheet'!F75/'Data Sheet'!F$66 -> 0.18821019 | H44: ='Data Sheet'!G75/'Data Sheet'!G$66 -> 0.058699447 | I44: ='Data Sheet'!H75/'Data Sheet'!H$66 -> 0.057030607 | J44: ='Data Sheet'!I75/'Data Sheet'!I$66 -> 0.059895726 | ... L44: ='Data Sheet'!K75/'Data Sheet'!K$66 -> 0.061618021
B45: ='[2]Data Sheet'!A67 -> Receivables | C45: ='Data Sheet'!B67/'Data Sheet'!B$66 -> 0.085445819 | D45: ='Data Sheet'!C67/'Data Sheet'!C$66 -> 0.06908188 | E45: ='Data Sheet'!D67/'Data Sheet'!D$66 -> 0.073340052 | F45: ='Data Sheet'!E67/'Data Sheet'!E$66 -> 0.09748242 | G45: ='Data Sheet'!F67/'Data Sheet'!F$66 -> 0.057013844 | H45: ='Data Sheet'!G67/'Data Sheet'!G$66 -> 0.025574629 | I45: ='Data Sheet'!H67/'Data Sheet'!H$66 -> 0.031713613 | J45: ='Data Sheet'!I67/'Data Sheet'!I$66 -> 0.04213364 | ... L45: ='Data Sheet'!K67/'Data Sheet'!K$66 -> 0.047819391
B46: ='[2]Data Sheet'!A68 -> Inventory | C46: ='Data Sheet'!B68/'Data Sheet'!B$66 -> 0.18427635 | D46: ='Data Sheet'!C68/'Data Sheet'!C$66 -> 0.1617853 | E46: ='Data Sheet'!D68/'Data Sheet'!D$66 -> 0.14068973 | F46: ='Data Sheet'!E68/'Data Sheet'!E$66 -> 0.13817167 | G46: ='Data Sheet'!F68/'Data Sheet'!F$66 -> 0.13729966 | H46: ='Data Sheet'!G68/'Data Sheet'!G$66 -> 0.052065755 | I46: ='Data Sheet'!H68/'Data Sheet'!H$66 -> 0.058094347 | J46: ='Data Sheet'!I68/'Data Sheet'!I$66 -> 0.058171518 | ... L46: ='Data Sheet'!K68/'Data Sheet'!K$66 -> 0.055282171
B47: ='[2]Data Sheet'!A69 -> Cash & Bank | C47: ='Data Sheet'!B69/'Data Sheet'!B$66 -> 0.20340702 | D47: ='Data Sheet'!C69/'Data Sheet'!C$66 -> 0.11638864 | E47: ='Data Sheet'!D69/'Data Sheet'!D$66 -> 0.19510693 | F47: ='Data Sheet'!E69/'Data Sheet'!E$66 -> 0.20167481 | G47: ='Data Sheet'!F69/'Data Sheet'!F$66 -> 0.25370913 | H47: ='Data Sheet'!G69/'Data Sheet'!G$66 -> 0.065042188 | I47: ='Data Sheet'!H69/'Data Sheet'!H$66 -> 0.054548549 | J47: ='Data Sheet'!I69/'Data Sheet'!I$66 -> 0.064014669 | ... L47: ='Data Sheet'!K69/'Data Sheet'!K$66 -> 0.09458698

Sheet Ratio Analysis
B4: ='Data Sheet'!B1 -> HINDUSTAN UNILEVER LTD
B5: =CONCATENATE("(",B4," |"," BSE Code :",'Data Sheet'!B4,")") -> (HINDUSTAN UNILEVER LTD | BSE Code :500696)
B6: =CONCATENATE(,"INR ",'Data Sheet'!B8) -> INR 2528.9
B7: 52 week (High - INR 3,022.9 & Low - 2,136.0)
B10: ="Ratio Analysis of - "&'Data Sheet'!B1 -> Ratio Analysis of - HINDUSTAN UNILEVER LTD
B11: Years | C11: ='Data Sheet'!B16 -> 42460 | D11: ='Data Sheet'!C16 -> 42825 | E11: ='Data Sheet'!D16 -> 43190 | F11: ='Data Sheet'!E16 -> 43555 | G11: ='Data Sheet'!F16 -> 43921 | H11: ='Data Sheet'!G16 -> 44286 | I11: ='Data Sheet'!H16 -> 44651 | J11: ='Data Sheet'!I16 -> 45016 | ... L11: ='Data Sheet'!K16 -> 45747 | N11: Mean | O11: Median
B13: SalesGrowth | D13: =IFERROR(HistoricalFS!D14/HistoricalFS!C14-1,0) -> 0.030323743 | E13: =IFERROR(HistoricalFS!E14/HistoricalFS!D14-1,0) -> 0.071859357 | F13: =IFERROR(HistoricalFS!F14/HistoricalFS!E14-1,0) -> 0.10592207 | G13: =IFERROR(HistoricalFS!G14/HistoricalFS!F14-1,0) -> 0.012032562 | H13: =IFERROR(HistoricalFS!H14/HistoricalFS!G14-1,0) -> 0.18211296 | I13: =IFERROR(HistoricalFS!I14/HistoricalFS!H14-1,0) -> 0.11520796 | J13: =IFERROR(HistoricalFS!J14/HistoricalFS!I14-1,0) -> 0.15509286 | K13: =IFERROR(HistoricalFS!K14/HistoricalFS!J14-1,0) -> 0.021723341 | L13: =IFERROR(HistoricalFS!L14/HistoricalFS!K14-1,0) -> 0.019791263 | N13: =IFERROR(AVERAGE(D13:L13),0) -> 0.07934068 | O13: =IFERROR(MEDIAN(C13:L13),0) -> 0.071859357
B14: EBITDA Growth | D14: =IFERROR(HistoricalFS!D26/HistoricalFS!C26-1,0) -> 0.07072758 | E14: =IFERROR(HistoricalFS!E26/HistoricalFS!D26-1,0) -> 0.18505057 | F14: =IFERROR(HistoricalFS!F26/HistoricalFS!E26-1,0) -> 0.18415789 | G14: =IFERROR(HistoricalFS!G26/HistoricalFS!F26-1,0) -> 0.11047297 | H14: =IFERROR(HistoricalFS!H26/HistoricalFS!G26-1,0) -> 0.17898793 | I14: =IFERROR(HistoricalFS!I26/HistoricalFS!H26-1,0) -> 0.10588336 | J14: =IFERROR(HistoricalFS!J26/HistoricalFS!I26-1,0) -> 0.10033445 | K14: =IFERROR(HistoricalFS!K26/HistoricalFS!J26-1,0) -> 0.036191419 | L14: =IFERROR(HistoricalFS!L26/HistoricalFS!K26-1,0) -> 0.012552016 | N14: =IFERROR(AVERAGE(D14:L14),0) -> 0.10937313 | O14: =IFERROR(MEDIAN(C14:L14),0) -> 0.10588336
B15: EBIT Growth | D15: =IFERROR(HistoricalFS!D35/HistoricalFS!C35-1,0) -> 0.061004139 | E15: =IFERROR(HistoricalFS!E35/HistoricalFS!D35-1,0) -> 0.18368385 | F15: =IFERROR(HistoricalFS!F35/HistoricalFS!E35-1,0) -> 0.19143144 | G15: =IFERROR(HistoricalFS!G35/HistoricalFS!F35-1,0) -> 0.065423933 | H15: =IFERROR(HistoricalFS!H35/HistoricalFS!G35-1,0) -> 0.19110509 | I15: =IFERROR(HistoricalFS!I35/HistoricalFS!H35-1,0) -> 0.11504928 | J15: =IFERROR(HistoricalFS!J35/HistoricalFS!I35-1,0) -> 0.10572837 | K15: =IFERROR(HistoricalFS!K35/HistoricalFS!J35-1,0) -> 0.033282091 | L15: =IFERROR(HistoricalFS!L35/HistoricalFS!K35-1,0) -> 0.0033474671 | N15: =IFERROR(AVERAGE(D15:L15),0) -> 0.10556174 | O15: =IFERROR(MEDIAN(C15:L15),0) -> 0.10572837
B16: Net Profit Growth | D16: =IFERROR(HistoricalFS!D41/HistoricalFS!C41-1,0) -> 0.0544 | E16: =IFERROR(HistoricalFS!E41/HistoricalFS!D41-1,0) -> 0.051593323 | F16: =IFERROR(HistoricalFS!F41/HistoricalFS!E41-1,0) -> 0.22366522 | G16: =IFERROR(HistoricalFS!G41/HistoricalFS!F41-1,0) -> -0.053066038 | H16: =IFERROR(HistoricalFS!H41/HistoricalFS!G41-1,0) -> 0.081776671 | I16: =IFERROR(HistoricalFS!I41/HistoricalFS!H41-1,0) -> 0.14620107 | J16: =IFERROR(HistoricalFS!J41/HistoricalFS!I41-1,0) -> 0.07164379 | K16: =IFERROR(HistoricalFS!K41/HistoricalFS!J41-1,0) -> 0.13839425 | L16: =IFERROR(HistoricalFS!L41/HistoricalFS!K41-1,0) -> 0.027442371 | N16: =IFERROR(AVERAGE(D16:L16),0) -> 0.082450074 | O16: =IFERROR(MEDIAN(C16:L16),0) -> 0.07164379
B17: Dividend Growth | D17: =IFERROR(HistoricalFS!D49/HistoricalFS!C49-1,0) -> 0.059558573 | E17: =IFERROR(HistoricalFS!E49/HistoricalFS!D49-1,0) -> 0.25477591 | F17: =IFERROR(HistoricalFS!F49/HistoricalFS!E49-1,0) -> 0.17715836 | G17: =IFERROR(HistoricalFS!G49/HistoricalFS!F49-1,0) -> 0.10346941 | H17: =IFERROR(HistoricalFS!H49/HistoricalFS!G49-1,0) -> 0.13917182 | I17: =IFERROR(HistoricalFS!I49/HistoricalFS!H49-1,0) -> 0.10780432 | J17: =IFERROR(HistoricalFS!J49/HistoricalFS!I49-1,0) -> 0.11783697 | K17: =IFERROR(HistoricalFS!K49/HistoricalFS!J49-1,0) -> -0.023723569 | L17: =IFERROR(HistoricalFS!L49/HistoricalFS!K49-1,0) -> -0.012255679 | N17: =IFERROR(AVERAGE(D17:L17),0) -> 0.10264401 | O17: =IFERROR(MEDIAN(C17:L17),0) -> 0.10780432
B19: Gross Margin | C19: =IFERROR(HistoricalFS!C21,0) -> 0.43385323 | D19: =IFERROR(HistoricalFS!D21,0) -> 0.43685544 | E19: =IFERROR(HistoricalFS!E21,0) -> 0.45663244 | F19: =IFERROR(HistoricalFS!F21,0) -> 0.46372424 | G19: =IFERROR(HistoricalFS!G21,0) -> 0.48183898 | H19: =IFERROR(HistoricalFS!H21,0) -> 0.46200136 | I19: =IFERROR(HistoricalFS!I21,0) -> 0.44579186 | J19: =IFERROR(HistoricalFS!J21,0) -> 0.41596236 | ... L19: =IFERROR(HistoricalFS!L21,0) -> 0.45297128 | N19: =IFERROR(AVERAGE(C19:L19),0) -> 0.45059612 | O19: =IFERROR(MEDIAN(C19:L19),0) -> 0.45465063
B20: EBITDA Margin | C20: =IFERROR(HistoricalFS!C27,0) -> 0.18362021 | D20: =IFERROR(HistoricalFS!D27,0) -> 0.19082082 | E20: =IFERROR(HistoricalFS!E27,0) -> 0.21097201 | F20: =IFERROR(HistoricalFS!F27,0) -> 0.22589672 | G20: =IFERROR(HistoricalFS!G27,0) -> 0.24786969 | H20: =IFERROR(HistoricalFS!H27,0) -> 0.24721443 | I20: =IFERROR(HistoricalFS!I27,0) -> 0.24514739 | J20: =IFERROR(HistoricalFS!J27,0) -> 0.23352592 | ... L20: =IFERROR(HistoricalFS!L27,0) -> 0.23515153 | N20: =IFERROR(AVERAGE(C20:L20),0) -> 0.22570515 | O20: =IFERROR(MEDIAN(C20:L20),0) -> 0.23433873
B21: EBIT Margin | C21: =IFERROR(HistoricalFS!C35/HistoricalFS!C14,0) -> 0.17265271 | D21: =IFERROR(HistoricalFS!D35/HistoricalFS!D14,0) -> 0.17779386 | E21: =IFERROR(HistoricalFS!E35/HistoricalFS!E14,0) -> 0.19634266 | F21: =IFERROR(HistoricalFS!F35/HistoricalFS!F14,0) -> 0.21152379 | G21: =IFERROR(HistoricalFS!G35/HistoricalFS!G14,0) -> 0.22268306 | H21: =IFERROR(HistoricalFS!H35/HistoricalFS!H14,0) -> 0.22437697 | I21: =IFERROR(HistoricalFS!I35/HistoricalFS!I14,0) -> 0.22434504 | J21: =IFERROR(HistoricalFS!J35/HistoricalFS!J14,0) -> 0.21475735 | ... L21: =IFERROR(HistoricalFS!L35/HistoricalFS!L14,0) -> 0.21368483 | N21: =IFERROR(AVERAGE(C21:L21),0) -> 0.20753471 | O21: =IFERROR(MEDIAN(C21:L21),0) -> 0.21422109
B22: EBT Margin | C22: =IFERROR(HistoricalFS!C39,0) -> 0.17212453 | D22: =IFERROR(HistoricalFS!D39,0) -> 0.17673844 | E22: =IFERROR(HistoricalFS!E39,0) -> 0.1956112 | F22: =IFERROR(HistoricalFS!F39,0) -> 0.2106843 | G22: =IFERROR(HistoricalFS!G39,0) -> 0.21971696 | H22: =IFERROR(HistoricalFS!H39,0) -> 0.22188909 | I22: =IFERROR(HistoricalFS!I39,0) -> 0.22232391 | J22: =IFERROR(HistoricalFS!J39,0) -> 0.21287554 | ... L22: =IFERROR(HistoricalFS!L39,0) -> 0.20742701 | N22: =IFERROR(AVERAGE(C22:L22),0) -> 0.20511817 | O22: =IFERROR(MEDIAN(C22:L22),0) -> 0.21123753
B23: Net Profit Margin | C23: =IFERROR(HistoricalFS!C42,0) -> 0.33844765 | D23: =IFERROR(HistoricalFS!D42,0) -> 0.33731445 | E23: =IFERROR(HistoricalFS!E42,0) -> 0.29900762 | F23: =IFERROR(HistoricalFS!F42,0) -> 0.30717218 | G23: =IFERROR(HistoricalFS!G42,0) -> 0.27559776 | H23: =IFERROR(HistoricalFS!H42,0) -> 0.24973646 | I23: =IFERROR(HistoricalFS!I42,0) -> 0.25617496 | J23: =IFERROR(HistoricalFS!J42,0) -> 0.2482165 | ... L23: =IFERROR(HistoricalFS!L42,0) -> 0.28595433 | N23: =IFERROR(AVERAGE(C23:L23),0) -> 0.28755989 | O23: =IFERROR(MEDIAN(C23:L23),0) -> 0.28196564
B25: SalesExpenses%Sales | C25: =IFERROR(HistoricalFS!C24,0) -> 0.25023302 | D25: =IFERROR(HistoricalFS!D24,0) -> 0.24603462 | E25: =IFERROR(HistoricalFS!E24,0) -> 0.24566043 | F25: =IFERROR(HistoricalFS!F24,0) -> 0.23782752 | G25: =IFERROR(HistoricalFS!G24,0) -> 0.23396928 | H25: =IFERROR(HistoricalFS!H24,0) -> 0.21478694 | I25: =IFERROR(HistoricalFS!I24,0) -> 0.20064447 | J25: =IFERROR(HistoricalFS!J24,0) -> 0.18243645 | ... L25: =IFERROR(HistoricalFS!L24,0) -> 0.21781974 | N25: =IFERROR(AVERAGE(C25:L25),0) -> 0.22489097 | O25: =IFERROR(MEDIAN(C25:L25),0) -> 0.22673325
B26: Depreciation%Sales | C26: =IFERROR(HistoricalFS!C33,0) -> 0.010967501 | D26: =IFERROR(HistoricalFS!D33,0) -> 0.013026959 | E26: =IFERROR(HistoricalFS!E33,0) -> 0.014629343 | F26: =IFERROR(HistoricalFS!F33,0) -> 0.014372933 | G26: =IFERROR(HistoricalFS!G33,0) -> 0.025186638 | H26: =IFERROR(HistoricalFS!H33,0) -> 0.022837459 | I26: =IFERROR(HistoricalFS!I33,0) -> 0.020802349 | J26: =IFERROR(HistoricalFS!J33,0) -> 0.01876857 | ... L26: =IFERROR(HistoricalFS!L33,0) -> 0.021466707 | N26: =IFERROR(AVERAGE(C26:L26),0) -> 0.018170432 | O26: =IFERROR(MEDIAN(C26:L26),0) -> 0.019207214
B27: OperatingIncome%Sales | C27: =IFERROR('Ratio Analysis'!C21,0) -> 0.17265271 | D27: =IFERROR('Ratio Analysis'!D21,0) -> 0.17779386 | E27: =IFERROR('Ratio Analysis'!E21,0) -> 0.19634266 | F27: =IFERROR('Ratio Analysis'!F21,0) -> 0.21152379 | G27: =IFERROR('Ratio Analysis'!G21,0) -> 0.22268306 | H27: =IFERROR('Ratio Analysis'!H21,0) -> 0.22437697 | I27: =IFERROR('Ratio Analysis'!I21,0) -> 0.22434504 | J27: =IFERROR('Ratio Analysis'!J21,0) -> 0.21475735 | ... L27: =IFERROR('Ratio Analysis'!L21,0) -> 0.21368483 | N27: =IFERROR(AVERAGE(C27:L27),0) -> 0.20753471 | O27: =IFERROR(MEDIAN(C27:L27),0) -> 0.21422109
B29: Return on Capital Employed | C29: =IFERROR((HistoricalFS!C35)/(SUM(HistoricalFS!C71:C73)),0) -> 0.82325926 | D29: =IFERROR((HistoricalFS!D35)/(SUM(HistoricalFS!D71:D73)),0) -> 0.83976642 | E29: =IFERROR((HistoricalFS!E35)/(SUM(HistoricalFS!E71:E73)),0) -> 0.95852218 | F29: =IFERROR((HistoricalFS!F35)/(SUM(HistoricalFS!F71:F73)),0) -> 1.0438112 | G29: =IFERROR((HistoricalFS!G35)/(SUM(HistoricalFS!G71:G73)),0) -> 1.0765585 | H29: =IFERROR((HistoricalFS!H35)/(SUM(HistoricalFS!H71:H73)),0) -> 0.22133658 | I29: =IFERROR((HistoricalFS!I35)/(SUM(HistoricalFS!I71:I73)),0) -> 0.23483155 | J29: =IFERROR((HistoricalFS!J35)/(SUM(HistoricalFS!J71:J73)),0) -> 0.25250859 | ... L29: =IFERROR((HistoricalFS!L35)/(SUM(HistoricalFS!L71:L73)),0) -> 0.26421156 | N29: =IFERROR(AVERAGE(C29:L29),0) -> 0.59698815 | O29: =IFERROR(MEDIAN(C29:L29),0) -> 0.54373541
B30: Retained Earnings% | C30: =IFERROR(HistoricalFS!C55,0) -> 0.057025921 | D30: =IFERROR(HistoricalFS!D55,0) -> 0.054582904 | E30: =IFERROR(HistoricalFS!E55,0) -> 0.11366434 | F30: =IFERROR(HistoricalFS!F55,0) -> 0.17183688 | G30: =IFERROR(HistoricalFS!G55,0) -> 0.14718888 | H30: =IFERROR(HistoricalFS!H55,0) -> 0 | I30: =IFERROR(HistoricalFS!I55,0) -> 0.078750144 | J30: =IFERROR(HistoricalFS!J55,0) -> 0.054667354 | ... L30: =IFERROR(HistoricalFS!L55,0) -> 0 | N30: =IFERROR(AVERAGE(C30:L30),0) -> 0.067771642 | O30: =IFERROR(MEDIAN(C30:L30),0) -> 0.055846638
B31: Return on Equity% | C31: =IFERROR(HistoricalFS!C44/SUM(HistoricalFS!C71:C72),0) -> 0.55758406 | D31: =IFERROR(HistoricalFS!D44/SUM(HistoricalFS!D71:D72),0) -> 0.57591934 | E31: =IFERROR(HistoricalFS!E44/SUM(HistoricalFS!E71:E72),0) -> 0.66941354 | F31: =IFERROR(HistoricalFS!F44/SUM(HistoricalFS!F71:F72),0) -> 0.72937587 | G31: =IFERROR(HistoricalFS!G44/SUM(HistoricalFS!G71:G72),0) -> 0.76947381 | H31: =IFERROR(HistoricalFS!H44/SUM(HistoricalFS!H71:H72),0) -> 0.16421949 | I31: =IFERROR(HistoricalFS!I44/SUM(HistoricalFS!I71:I72),0) -> 0.17677993 | J31: =IFERROR(HistoricalFS!J44/SUM(HistoricalFS!J71:J72),0) -> 0.19272821 | ... L31: =IFERROR(HistoricalFS!L44/SUM(HistoricalFS!L71:L72),0) -> 0.18924335 | N31: =IFERROR(AVERAGE(C31:L31),0) -> 0.42095359 | O31: =IFERROR(MEDIAN(C31:L31),0) -> 0.37515613
B32: Self Sustained Growth Rate | C32: =IFERROR(C30*C31,0) -> 0.031796744 | D32: =IFERROR(D30*D31,0) -> 0.03143535 | E32: =IFERROR(E30*E31,0) -> 0.076088449 | F32: =IFERROR(F30*F31,0) -> 0.12533367 | G32: =IFERROR(G30*G31,0) -> 0.11325799 | H32: =IFERROR(H30*H31,0) -> 0 | I32: =IFERROR(I30*I31,0) -> 0.013921445 | J32: =IFERROR(J30*J31,0) -> 0.010535941 | ... L32: =IFERROR(L30*L31,0) -> 0 | N32: =IFERROR(AVERAGE(C32:L32),0) -> 0.040236959 | O32: =IFERROR(MEDIAN(C32:L32),0) -> 0.022678397
B33: Interest Coverage Ratio | C33: =IFERROR(HistoricalFS!C35/HistoricalFS!C29,0) -> 326.88235 | D33: =IFERROR(HistoricalFS!D35/HistoricalFS!D29,0) -> 168.45714 | E33: =IFERROR(HistoricalFS!E35/HistoricalFS!E29,0) -> 268.42308 | F33: =IFERROR(HistoricalFS!F35/HistoricalFS!F29,0) -> 251.9697 | G33: =IFERROR(HistoricalFS!G35/HistoricalFS!G29,0) -> 75.076271 | H33: =IFERROR(HistoricalFS!H35/HistoricalFS!H29,0) -> 90.188034 | I33: =IFERROR(HistoricalFS!I35/HistoricalFS!I29,0) -> 111 | J33: =IFERROR(HistoricalFS!J35/HistoricalFS!J29,0) -> 114.12281 | ... L33: =IFERROR(HistoricalFS!L35/HistoricalFS!L29,0) -> 34.146835 | N33: =IFERROR(AVERAGE(C33:L33),0) -> 148.05147 | O33: =IFERROR(MEDIAN(C33:L33),0) -> 112.5614
B35: Debtor Turnover Ratio | C35: =IFERROR(HistoricalFS!C14/HistoricalFS!C83,0) -> 25.463608 | D35: =IFERROR(HistoricalFS!D14/HistoricalFS!D83,0) -> 30.564055 | E35: =IFERROR(HistoricalFS!E14/HistoricalFS!E83,0) -> 27.133588 | F35: =IFERROR(HistoricalFS!F14/HistoricalFS!F83,0) -> 21.646476 | G35: =IFERROR(HistoricalFS!G14/HistoricalFS!G83,0) -> 34.624021 | H35: =IFERROR(HistoricalFS!H14/HistoricalFS!H83,0) -> 26.750853 | I35: =IFERROR(HistoricalFS!I14/HistoricalFS!I83,0) -> 23.455277 | J35: =IFERROR(HistoricalFS!J14/HistoricalFS!J83,0) -> 19.675219 | ... L35: =IFERROR(HistoricalFS!L14/HistoricalFS!L83,0) -> 16.528149 | N35: =IFERROR(AVERAGE(C35:L35),0) -> 24.64939 | O35: =IFERROR(MEDIAN(C35:L35),0) -> 24.459442
B36: Creditor Turnover Ratio | C36: =IFERROR(HistoricalFS!C14/HistoricalFS!C74,0) -> 4.0017406 | D36: =IFERROR(HistoricalFS!D14/HistoricalFS!D74,0) -> 3.8183074 | E36: =IFERROR(HistoricalFS!E14/HistoricalFS!E74,0) -> 3.3593233 | F36: =IFERROR(HistoricalFS!F14/HistoricalFS!F74,0) -> 3.6865798 | G36: =IFERROR(HistoricalFS!G14/HistoricalFS!G74,0) -> 3.3363804 | H36: =IFERROR(HistoricalFS!H14/HistoricalFS!H74,0) -> 2.2324124 | I36: =IFERROR(HistoricalFS!I14/HistoricalFS!I74,0) -> 2.5706303 | J36: =IFERROR(HistoricalFS!J14/HistoricalFS!J74,0) -> 2.8106152 | ... L36: =IFERROR(HistoricalFS!L14/HistoricalFS!L74,0) -> 2.1907125 | N36: =IFERROR(AVERAGE(C36:L36),0) -> 3.0406981 | O36: =IFERROR(MEDIAN(C36:L36),0) -> 3.0734978
B37: Inventory Turnover | C37: =IFERROR(HistoricalFS!C14/HistoricalFS!C84,0) -> 11.807043 | D37: =IFERROR(HistoricalFS!D14/HistoricalFS!D84,0) -> 13.050767 | E37: =IFERROR(HistoricalFS!E14/HistoricalFS!E84,0) -> 14.144449 | F37: =IFERROR(HistoricalFS!F14/HistoricalFS!F84,0) -> 15.27195 | G37: =IFERROR(HistoricalFS!G14/HistoricalFS!G84,0) -> 14.377665 | H37: =IFERROR(HistoricalFS!H14/HistoricalFS!H84,0) -> 13.139983 | I37: =IFERROR(HistoricalFS!I14/HistoricalFS!I84,0) -> 12.804199 | J37: =IFERROR(HistoricalFS!J14/HistoricalFS!J84,0) -> 14.250765 | ... L37: =IFERROR(HistoricalFS!L14/HistoricalFS!L84,0) -> 14.296942 | N37: =IFERROR(AVERAGE(C37:L37),0) -> 13.853312 | O37: =IFERROR(MEDIAN(C37:L37),0) -> 14.197607
B38: Fixed Asset Turnover | C38: =IFERROR(HistoricalFS!C14/HistoricalFS!C77,0) -> 9.8790669 | D38: =IFERROR(HistoricalFS!D14/HistoricalFS!D77,0) -> 7.5044128 | E38: =IFERROR(HistoricalFS!E14/HistoricalFS!E77,0) -> 7.8500442 | F38: =IFERROR(HistoricalFS!F14/HistoricalFS!F77,0) -> 8.3372216 | G38: =IFERROR(HistoricalFS!G14/HistoricalFS!G77,0) -> 7.2609965 | H38: =IFERROR(HistoricalFS!H14/HistoricalFS!H77,0) -> 0.91417686 | I38: =IFERROR(HistoricalFS!I14/HistoricalFS!I77,0) -> 1.0189031 | J38: =IFERROR(HistoricalFS!J14/HistoricalFS!J77,0) -> 1.1500057 | ... L38: =IFERROR(HistoricalFS!L14/HistoricalFS!L77,0) -> 1.1617006 | N38: =IFERROR(AVERAGE(C38:L38),0) -> 4.622821 | O38: =IFERROR(MEDIAN(C38:L38),0) -> 4.2113485
B39: Capital Turnover Ratio | C39: =IFERROR(HistoricalFS!C14/SUM(HistoricalFS!C71:C72),0) -> 4.8966986 | D39: =IFERROR(HistoricalFS!D14/SUM(HistoricalFS!D71:D72),0) -> 4.9172598 | E39: =IFERROR(HistoricalFS!E14/SUM(HistoricalFS!E71:E72),0) -> 4.8818844 | F39: =IFERROR(HistoricalFS!F14/SUM(HistoricalFS!F71:F72),0) -> 4.9968222 | G39: =IFERROR(HistoricalFS!G14/SUM(HistoricalFS!G71:G72),0) -> 4.8344878 | H39: =IFERROR(HistoricalFS!H14/SUM(HistoricalFS!H71:H72),0) -> 0.98644964 | I39: =IFERROR(HistoricalFS!I14/SUM(HistoricalFS!I71:I72),0) -> 1.0689957 | J39: =IFERROR(HistoricalFS!J14/SUM(HistoricalFS!J71:J72),0) -> 1.204278 | ... L39: =IFERROR(HistoricalFS!L14/SUM(HistoricalFS!L71:L72),0) -> 1.2777013 | N39: =IFERROR(AVERAGE(C39:L39),0) -> 3.0273059 | O39: =IFERROR(MEDIAN(C39:L39),0) -> 3.0560945
B41: ( in days)
B42: Debtor Days | C42: =IFERROR(365/C35,0) -> 14.334183 | D42: =IFERROR(365/D35,0) -> 11.942133 | E42: =IFERROR(365/E35,0) -> 13.451962 | F42: =IFERROR(365/F35,0) -> 16.861867 | G42: =IFERROR(365/G35,0) -> 10.541814 | H42: =IFERROR(365/H35,0) -> 13.644425 | I42: =IFERROR(365/I35,0) -> 15.56153 | J42: =IFERROR(365/J35,0) -> 18.551255 | ... L42: =IFERROR(365/L35,0) -> 22.083538 | N42: =IFERROR(AVERAGE(C42:L42),0) -> 15.464598 | O42: =IFERROR(MEDIAN(C42:L42),0) -> 14.947856
B43: Payable Days | C43: =IFERROR(365/C36,0) -> 91.210309 | D43: =IFERROR(365/D36,0) -> 95.592093 | E43: =IFERROR(365/E36,0) -> 108.65283 | F43: =IFERROR(365/F36,0) -> 99.007759 | G43: =IFERROR(365/G36,0) -> 109.39999 | H43: =IFERROR(365/H36,0) -> 163.50026 | I43: =IFERROR(365/I36,0) -> 141.98852 | J43: =IFERROR(365/J36,0) -> 129.86481 | ... L43: =IFERROR(365/L36,0) -> 166.61246 | N43: =IFERROR(AVERAGE(C43:L43),0) -> 125.78947 | O43: =IFERROR(MEDIAN(C43:L43),0) -> 119.6324
B44: Inventory Days | C44: =IFERROR(365/C37,0) -> 30.913751 | D44: =IFERROR(365/D37,0) -> 27.967704 | E44: =IFERROR(365/E37,0) -> 25.805177 | F44: =IFERROR(365/F37,0) -> 23.900025 | G44: =IFERROR(365/G37,0) -> 25.386597 | H44: =IFERROR(365/H37,0) -> 27.777813 | I44: =IFERROR(365/I37,0) -> 28.506273 | J44: =IFERROR(365/J37,0) -> 25.612661 | ... L44: =IFERROR(365/L37,0) -> 25.529935 | N44: =IFERROR(AVERAGE(C44:L44),0) -> 26.511762 | O44: =IFERROR(MEDIAN(C44:L44),0) -> 25.708919
B45: Cash Conversion Cycle | C45: =SUM(C42,C44)-C43 -> -45.962375 | D45: =SUM(D42,D44)-D43 -> -55.682257 | E45: =SUM(E42,E44)-E43 -> -69.395696 | F45: =SUM(F42,F44)-F43 -> -58.245866 | G45: =SUM(G42,G44)-G43 -> -73.471583 | H45: =SUM(H42,H44)-H43 -> -122.07802 | I45: =SUM(I42,I44)-I43 -> -97.920718 | J45: =SUM(J42,J44)-J43 -> -85.700891 | ... L45: =SUM(L42,L44)-L43 -> -118.99899 | N45: =IFERROR(AVERAGE(C45:L45),0) -> -83.813107 | O45: =IFERROR(MEDIAN(C45:L45),0) -> -79.586237
B47: CFO/Sales | C47: =IFERROR(HistoricalFS!C94/HistoricalFS!C14,0) -> 0.12959051 | D47: =IFERROR(HistoricalFS!D94/HistoricalFS!D14,0) -> 0.15635366 | E47: =IFERROR(HistoricalFS!E94/HistoricalFS!E14,0) -> 0.17045998 | F47: =IFERROR(HistoricalFS!F94/HistoricalFS!F14,0) -> 0.14754515 | G47: =IFERROR(HistoricalFS!G94/HistoricalFS!G14,0) -> 0.19161451 | H47: =IFERROR(HistoricalFS!H94/HistoricalFS!H14,0) -> 0.19484137 | I47: =IFERROR(HistoricalFS!I94/HistoricalFS!I14,0) -> 0.17252031 | J47: =IFERROR(HistoricalFS!J94/HistoricalFS!J14,0) -> 0.16492242 | ... L47: =IFERROR(HistoricalFS!L94/HistoricalFS!L14,0) -> 0.188305 | N47: =IFERROR(AVERAGE(C47:L47),0) -> 0.17660721 | O47: =IFERROR(MEDIAN(C47:L47),0) -> 0.17149014
B48: CFO/Total Assets | C48: =IFERROR(HistoricalFS!C94/HistoricalFS!C88,0) -> 0.28195768 | D48: =IFERROR(HistoricalFS!D94/HistoricalFS!D88,0) -> 0.33012861 | E48: =IFERROR(HistoricalFS!E94/HistoricalFS!E88,0) -> 0.33921173 | F48: =IFERROR(HistoricalFS!F94/HistoricalFS!F88,0) -> 0.31134253 | G48: =IFERROR(HistoricalFS!G94/HistoricalFS!G88,0) -> 0.37825634 | H48: =IFERROR(HistoricalFS!H94/HistoricalFS!H88,0) -> 0.13329939 | I48: =IFERROR(HistoricalFS!I94/HistoricalFS!I88,0) -> 0.1283295 | J48: =IFERROR(HistoricalFS!J94/HistoricalFS!J88,0) -> 0.1367188 | ... L48: =IFERROR(HistoricalFS!L94/HistoricalFS!L88,0) -> 0.14882987 | N48: =IFERROR(AVERAGE(C48:L48),0) -> 0.23851594 | O48: =IFERROR(MEDIAN(C48:L48),0) -> 0.23952131
B49: CFO/Total Debt | C49: =IFERROR(HistoricalFS!C94/HistoricalFS!C73,0) -> 23.564972 | D49: =IFERROR(HistoricalFS!D94/HistoricalFS!D73,0) -> 18.718412 | E49: =IFERROR(HistoricalFS!E94/HistoricalFS!E73,0) -> 0 | F49: =IFERROR(HistoricalFS!F94/HistoricalFS!F73,0) -> 58.585859 | G49: =IFERROR(HistoricalFS!G94/HistoricalFS!G73,0) -> 0 | H49: =IFERROR(HistoricalFS!H94/HistoricalFS!H73,0) -> 0 | I49: =IFERROR(HistoricalFS!I94/HistoricalFS!I73,0) -> 8.674976 | J49: =IFERROR(HistoricalFS!J94/HistoricalFS!J73,0) -> 8.1960623 | ... L49: =IFERROR(HistoricalFS!L94/HistoricalFS!L73,0) -> 7.2123786 | N49: =IFERROR(AVERAGE(C49:L49),0) -> 13.537651 | O49: =IFERROR(MEDIAN(C49:L49),0) -> 8.4355192

Sheet forcasting
B3: ='Data Sheet'!B1 -> HINDUSTAN UNILEVER LTD
B4: =CONCATENATE("(",B3," |"," BSE Code :",'Data Sheet'!B4,")") -> (HINDUSTAN UNILEVER LTD | BSE Code :500696)
B5: =CONCATENATE(,"INR ",'Data Sheet'!B8) -> INR 2528.9
B6: 52 week (High - INR 3,022.9 & Low - 2,136.0)
B9: ='Data Sheet'!$B$1&" - "&"EBITDA"&" Forecasting" -> HINDUSTAN UNILEVER LTD - EBITDA Forecasting | G9: ='Data Sheet'!$B$1&" - "&"EBITDA"&" Forecasting" -> HINDUSTAN UNILEVER LTD - EBITDA Forecasting | L9: ='Data Sheet'!$B$1&" - "&"Earnings Per Share"&" Forecasting" -> HINDUSTAN UNILEVER LTD - Earnings Per Share Forecasting
B10: Year Weight | C10: Year | D10: Sales | E10: Sales Growth | G10: Year Weight | H10: Year | I10: EBITDA | J10: EBITDAGrowth | L10: Year Weight | M10: Year | N10: EPS | O10: Sales Growth
B11: 1 | C11: ='Data Sheet'!$B$16 -> 42460 | D11: {=TRANSPOSE('Data Sheet'!B17:K17)} -> 32186 | G11: 1 | H11: ='Data Sheet'!$B$16 -> 42460 | I11: {=TRANSPOSE('Data Sheet'!B33:K33)} -> 6396 | L11: 1 | M11: ='Data Sheet'!$B$16 -> 42460 | N11: {=TRANSPOSE(HistoricalFS!C49:L49)} -> 16.937012
B12: =B11+1 -> 2 | C12: =C11+365 -> 42825 | D12: 33162 | E12: =D12/D11-1 -> 0.030323743 | G12: =G11+1 -> 2 | H12: =H11+365 -> 42825 | I12: 6920 | J12: =I12/I11-1 -> 0.081926204 | L12: =L11+1 -> 2 | M12: =M11+365 -> 42825 | N12: 17.945756 | O12: =N12/N11-1 -> 0.059558573
B13: =B12+1 -> 3 | C13: =C12+365 -> 43190 | D13: 35545 | E13: =D13/D12-1 -> 0.071859357 | G13: =G12+1 -> 3 | H13: =H12+365 -> 43190 | I13: 7839 | J13: =I13/I12-1 -> 0.13280347 | L13: =L12+1 -> 3 | M13: =M12+365 -> 43190 | N13: 22.517903 | O13: =N13/N12-1 -> 0.25477591
B14: =B13+1 -> 4 | C14: =C13+365 -> 43555 | D14: 39310 | E14: =D14/D13-1 -> 0.10592207 | G14: =G13+1 -> 4 | H14: =H13+365 -> 43555 | I14: 9196 | J14: =I14/I13-1 -> 0.17310881 | L14: =L13+1 -> 4 | M14: =M13+365 -> 43555 | N14: 26.507137 | O14: =N14/N13-1 -> 0.17715836
B15: =B14+1 -> 5 | C15: =C14+365 -> 43920 | D15: 39783 | E15: =D15/D14-1 -> 0.012032562 | G15: =G14+1 -> 5 | H15: =H14+365 -> 43920 | I15: 10277 | J15: =I15/I14-1 -> 0.11755111 | L15: =L14+1 -> 5 | M15: =M14+365 -> 43920 | N15: 29.249815 | O15: =N15/N14-1 -> 0.10346941
B16: =B15+1 -> 6 | C16: =C15+365 -> 44285 | D16: 47028 | E16: =D16/D15-1 -> 0.18211296 | G16: =G15+1 -> 6 | H16: =H15+365 -> 44285 | I16: 11792 | J16: =I16/I15-1 -> 0.14741656 | L16: =L15+1 -> 6 | M16: =M15+365 -> 44285 | N16: 33.320565 | O16: =N16/N15-1 -> 0.13917182
B17: =B16+1 -> 7 | C17: =C16+365 -> 44650 | D17: 52446 | E17: =D17/D16-1 -> 0.11520796 | G17: =G16+1 -> 7 | H17: =H16+365 -> 44650 | I17: 13063 | J17: =I17/I16-1 -> 0.10778494 | L17: =L16+1 -> 7 | M17: =M16+365 -> 44650 | N17: 36.912666 | O17: =N17/N16-1 -> 0.10780432
B18: =B17+1 -> 8 | C18: =C17+365 -> 45015 | D18: 60580 | E18: =D18/D17-1 -> 0.15509286 | G18: =G17+1 -> 8 | H18: =H17+365 -> 45015 | I18: 14572 | J18: =I18/I17-1 -> 0.11551711 | L18: =L17+1 -> 8 | M18: =M17+365 -> 45015 | N18: 41.262343 | O18: =N18/N17-1 -> 0.11783697
B19: =B18+1 -> 9 | C19: =C18+365 -> 45380 | D19: 61896 | E19: =D19/D18-1 -> 0.021723341 | G19: =G18+1 -> 9 | H19: =H18+365 -> 45380 | I19: 15471 | J19: =I19/I18-1 -> 0.061693659 | L19: =L18+1 -> 9 | M19: =M18+365 -> 45380 | N19: 40.283453 | O19: =N19/N18-1 -> -0.023723569
B20: =B19+1 -> 10 | C20: =C19+365 -> 45745 | D20: 63121 | E20: =D20/D19-1 -> 0.019791263 | G20: =G19+1 -> 10 | H20: =H19+365 -> 45745 | I20: 16143 | J20: =I20/I19-1 -> 0.043436106 | L20: =L19+1 -> 10 | M20: =M19+365 -> 45745 | N20: 39.789751 | O20: =N20/N19-1 -> -0.012255679
B21: =B20+1 -> 11 | C21: =C20+365 -> 46110 | D21: =FORECAST(B21,$D$11:$D$20,$B$11:$B$20) -> 68218.4 | E21: =D21/D20-1 -> 0.080756008 | G21: =G20+1 -> 11 | H21: =H20+365 -> 46110 | I21: =FORECAST(G21,$I$11:$I$20,$G$11:$G$20) -> 17645.6 | J21: =I21/I20-1 -> 0.093080592 | L21: =L20+1 -> 11 | M21: =M20+365 -> 46110 | N21: =FORECAST(L21,$N$11:$N$20,$L$11:$L$20) -> 46.840909 | O21: =N21/N20-1 -> 0.17721039
